Workbook

Sheet base_nuevo_leon
A1: año | B1: sexo | C1: edad_inicio | D1: n | E1: ax | F1: poblacion | G1: defunciones | H1: mx | I1: qx | J1: lx | K1: dx | L1: Lx | M1: Tx | N1: ex | P1: APV_85
A2: 2010 | B2: Hombres | C2: 0 | D2: 1 | E2: 0.1 | F2: 36094 | G2: 218.42 | H2: =IFERROR(G2/F2,0) -> 0.0060514213 | I2: =IF(C2=85,1,(D2*H2)/(1+(D2-IF(E2="",D2/2,E2))*H2)) -> 0.0060186421 | J2: =IF(OR(ROW()=2,A2<>A1,B2<>B1),100000,J1-K1) -> 100000 | K2: =J2*I2 -> 601.86421 | L2: =IF(C2=85,J2/H2,D2*J2-(D2-E2)*K2) -> 99458.322 | M2: =SUMIFS(L:L,A:A,A2,B:B,B2,C:C,">="&C2) -> 7459995.1 | N2: =M2/J2 -> 74.599951 | P2: =IF(C2=0, 85-N2, "") -> 10.400049
A3: 2010 | B3: Hombres | C3: 1 | D3: 4 | E3: 2 | F3: 144378 | G3: 57.98 | H3: =IFERROR(G3/F3,0) -> 0.00040158473 | I3: =IF(C3=85,1,(D3*H3)/(1+(D3-IF(E3="",D3/2,E3))*H3)) -> 0.0016050498 | J3: =IF(OR(ROW()=2,A3<>A2,B3<>B2),100000,J2-K2) -> 99398.136 | K3: =J3*I3 -> 159.53896 | L3: =IF(C3=85,J3/H3,D3*J3-(D3-E3)*K3) -> 397273.47 | M3: =SUMIFS(L:L,A:A,A3,B:B,B3,C:C,">="&C3) -> 7360536.7 | N3: =M3/J3 -> 74.051054 | P3: =IF(C3=0, 85-N3, "")
A4: 2010 | B4: Hombres | C4: 5 | D4: 5 | E4: 2.5 | F4: 192504 | G4: 30.91 | H4: =IFERROR(G4/F4,0) -> 0.00016056809 | I4: =IF(C4=85,1,(D4*H4)/(1+(D4-IF(E4="",D4/2,E4))*H4)) -> 0.00080251831 | J4: =IF(OR(ROW()=2,A4<>A3,B4<>B3),100000,J3-K3) -> 99238.597 | K4: =J4*I4 -> 79.640791 | L4: =IF(C4=85,J4/H4,D4*J4-(D4-E4)*K4) -> 495993.88 | M4: =SUMIFS(L:L,A:A,A4,B:B,B4,C:C,">="&C4) -> 6963263.3 | N4: =M4/J4 -> 70.166886 | P4: =IF(C4=0, 85-N4, "")
A5: 2010 | B5: Hombres | C5: 10 | D5: 5 | E5: 2.5 | F5: 192504 | G5: 41.22 | H5: =IFERROR(G5/F5,0) -> 0.00021412542 | I5: =IF(C5=85,1,(D5*H5)/(1+(D5-IF(E5="",D5/2,E5))*H5)) -> 0.0010700543 | J5: =IF(OR(ROW()=2,A5<>A4,B5<>B4),100000,J4-K4) -> 99158.956 | K5: =J5*I5 -> 106.10547 | L5: =IF(C5=85,J5/H5,D5*J5-(D5-E5)*K5) -> 495529.52 | M5: =SUMIFS(L:L,A:A,A5,B:B,B5,C:C,">="&C5) -> 6467269.4 | N5: =M5/J5 -> 65.221233 | P5: =IF(C5=0, 85-N5, "")
A6: 2010 | B6: Hombres | C6: 15 | D6: 5 | E6: 2.5 | F6: 180472 | G6: 87 | H6: =IFERROR(G6/F6,0) -> 0.00048206924 | I6: =IF(C6=85,1,(D6*H6)/(1+(D6-IF(E6="",D6/2,E6))*H6)) -> 0.0024074448 | J6: =IF(OR(ROW()=2,A6<>A5,B6<>B5),100000,J5-K5) -> 99052.851 | K6: =J6*I6 -> 238.46427 | L6: =IF(C6=85,J6/H6,D6*J6-(D6-E6)*K6) -> 494668.09 | M6: =SUMIFS(L:L,A:A,A6,B:B,B6,C:C,">="&C6) -> 5971739.9 | N6: =M6/J6 -> 60.28842 | P6: =IF(C6=0, 85-N6, "")
A7: 2010 | B7: Hombres | C7: 20 | D7: 5 | E7: 2.5 | F7: 180472 | G7: 145.11 | H7: =IFERROR(G7/F7,0) -> 0.00080405825 | I7: =IF(C7=85,1,(D7*H7)/(1+(D7-IF(E7="",D7/2,E7))*H7)) -> 0.0040122261 | J7: =IF(OR(ROW()=2,A7<>A6,B7<>B6),100000,J6-K6) -> 98814.386 | K7: =J7*I7 -> 396.46566 | L7: =IF(C7=85,J7/H7,D7*J7-(D7-E7)*K7) -> 493080.77 | M7: =SUMIFS(L:L,A:A,A7,B:B,B7,C:C,">="&C7) -> 5477071.8 | N7: =M7/J7 -> 55.427878 | P7: =IF(C7=0, 85-N7, "")
A8: 2010 | B8: Hombres | C8: 25 | D8: 5 | E8: 2.5 | F8: 168441 | G8: 180.71 | H8: =IFERROR(G8/F8,0) -> 0.0010728386 | I8: =IF(C8=85,1,(D8*H8)/(1+(D8-IF(E8="",D8/2,E8))*H8)) -> 0.005349844 | J8: =IF(OR(ROW()=2,A8<>A7,B8<>B7),100000,J7-K7) -> 98417.921 | K8: =J8*I8 -> 526.52052 | L8: =IF(C8=85,J8/H8,D8*J8-(D8-E8)*K8) -> 490773.3 | M8: =SUMIFS(L:L,A:A,A8,B:B,B8,C:C,">="&C8) -> 4983991 | N8: =M8/J8 -> 50.641092 | P8: =IF(C8=0, 85-N8, "")
A9: 2010 | B9: Hombres | C9: 30 | D9: 5 | E9: 2.5 | F9: 168441 | G9: 226.04 | H9: =IFERROR(G9/F9,0) -> 0.0013419536 | I9: =IF(C9=85,1,(D9*H9)/(1+(D9-IF(E9="",D9/2,E9))*H9)) -> 0.0066873326 | J9: =IF(OR(ROW()=2,A9<>A8,B9<>B8),100000,J8-K8) -> 97891.4 | K9: =J9*I9 -> 654.63235 | L9: =IF(C9=85,J9/H9,D9*J9-(D9-E9)*K9) -> 487820.42 | M9: =SUMIFS(L:L,A:A,A9,B:B,B9,C:C,">="&C9) -> 4493217.7 | N9: =M9/J9 -> 45.900025 | P9: =IF(C9=0, 85-N9, "")
A10: 2010 | B10: Hombres | C10: 35 | D10: 5 | E10: 2.5 | F10: 156409 | G10: 273.13 | H10: =IFERROR(G10/F10,0) -> 0.001746255 | I10: =IF(C10=85,1,(D10*H10)/(1+(D10-IF(E10="",D10/2,E10))*H10)) -> 0.0086933232 | J10: =IF(OR(ROW()=2,A10<>A9,B10<>B9),100000,J9-K9) -> 97236.768 | K10: =J10*I10 -> 845.31064 | L10: =IF(C10=85,J10/H10,D10*J10-(D10-E10)*K10) -> 484070.56 | M10: =SUMIFS(L:L,A:A,A10,B:B,B10,C:C,">="&C10) -> 4005397.3 | N10: =M10/J10 -> 41.192209 | P10: =IF(C10=0, 85-N10, "")
A11: 2010 | B11: Hombres | C11: 40 | D11: 5 | E11: 2.5 | F11: 144378 | G11: 349.68 | H11: =IFERROR(G11/F11,0) -> 0.0024219756 | I11: =IF(C11=85,1,(D11*H11)/(1+(D11-IF(E11="",D11/2,E11))*H11)) -> 0.012036995 | J11: =IF(OR(ROW()=2,A11<>A10,B11<>B10),100000,J10-K10) -> 96391.457 | K11: =J11*I11 -> 1160.2635 | L11: =IF(C11=85,J11/H11,D11*J11-(D11-E11)*K11) -> 479056.63 | M11: =SUMIFS(L:L,A:A,A11,B:B,B11,C:C,">="&C11) -> 3521326.7 | N11: =M11/J11 -> 36.531523 | P11: =IF(C11=0, 85-N11, "")
A12: 2010 | B12: Hombres | C12: 45 | D12: 5 | E12: 2.5 | F12: 132346 | G12: 500.3 | H12: =IFERROR(G12/F12,0) -> 0.0037802427 | I12: =IF(C12=85,1,(D12*H12)/(1+(D12-IF(E12="",D12/2,E12))*H12)) -> 0.018724258 | J12: =IF(OR(ROW()=2,A12<>A11,B12<>B11),100000,J11-K11) -> 95231.194 | K12: =J12*I12 -> 1783.1334 | L12: =IF(C12=85,J12/H12,D12*J12-(D12-E12)*K12) -> 471698.13 | M12: =SUMIFS(L:L,A:A,A12,B:B,B12,C:C,">="&C12) -> 3042270.1 | N12: =M12/J12 -> 31.946151 | P12: =IF(C12=0, 85-N12, "")
A13: 2010 | B13: Hombres | C13: 50 | D13: 5 | E13: 2.5 | F13: 120315 | G13: 718.6 | H13: =IFERROR(G13/F13,0) -> 0.0059726551 | I13: =IF(C13=85,1,(D13*H13)/(1+(D13-IF(E13="",D13/2,E13))*H13)) -> 0.029423928 | J13: =IF(OR(ROW()=2,A13<>A12,B13<>B12),100000,J12-K12) -> 93448.06 | K13: =J13*I13 -> 2749.609 | L13: =IF(C13=85,J13/H13,D13*J13-(D13-E13)*K13) -> 460366.28 | M13: =SUMIFS(L:L,A:A,A13,B:B,B13,C:C,">="&C13) -> 2570572 | N13: =M13/J13 -> 27.508029 | P13: =IF(C13=0, 85-N13, "")
... A19: 2010 | B19: Hombres | C19: 80 | D19: 5 | E19: 2.5 | F19: 48126 | G19: 4831.17 | H19: =IFERROR(G19/F19,0) -> 0.10038586 | I19: =IF(C19=85,1,(D19*H19)/(1+(D19-IF(E19="",D19/2,E19))*H19)) -> 0.40123381 | J19: =IF(OR(ROW()=2,A19<>A18,B19<>B18),100000,J18-K18) -> 42958.356 | K19: =J19*I19 -> 17236.345 | L19: =IF(C19=85,J19/H19,D19*J19-(D19-E19)*K19) -> 171700.92 | M19: =SUMIFS(L:L,A:A,A19,B:B,B19,C:C,">="&C19) -> 295165.15 | N19: =M19/J19 -> 6.8709601 | P19: =IF(C19=0, 85-N19, "")
A20: 2010 | B20: Hombres | C20: 85 | D20: 999 | F20: 36094 | G20: 7519.67 | H20: =IFERROR(G20/F20,0) -> 0.20833573 | I20: =IF(C20=85,1,(D20*H20)/(1+(D20-IF(E20="",D20/2,E20))*H20)) -> 1 | J20: =IF(OR(ROW()=2,A20<>A19,B20<>B19),100000,J19-K19) -> 25722.012 | K20: =J20*I20 -> 25722.012 | L20: =IF(C20=85,J20/H20,D20*J20-(D20-E20)*K20) -> 123464.23 | M20: =SUMIFS(L:L,A:A,A20,B:B,B20,C:C,">="&C20) -> 123464.23 | N20: =M20/J20 -> 4.7999447 | P20: =IF(C20=0, 85-N20, "")
A21: 2010 | B21: Mujeres | C21: 0 | D21: 1 | E21: 0.1 | F21: 36239 | G21: 137.09 | H21: =IFERROR(G21/F21,0) -> 0.003782941 | I21: =IF(C21=85,1,(D21*H21)/(1+(D21-IF(E21="",D21/2,E21))*H21)) -> 0.0037701052 | J21: =IF(OR(ROW()=2,A21<>A20,B21<>B20),100000,J20-K20) -> 100000 | K21: =J21*I21 -> 377.01052 | L21: =IF(C21=85,J21/H21,D21*J21-(D21-E21)*K21) -> 99660.691 | M21: =SUMIFS(L:L,A:A,A21,B:B,B21,C:C,">="&C21) -> 8029999.9 | N21: =M21/J21 -> 80.299999 | P21: =IF(C21=0, 85-N21, "") -> 4.7000012
A22: 2010 | B22: Mujeres | C22: 1 | D22: 4 | E22: 2 | F22: 144956 | G22: 32.37 | H22: =IFERROR(G22/F22,0) -> 0.00022330914 | I22: =IF(C22=85,1,(D22*H22)/(1+(D22-IF(E22="",D22/2,E22))*H22)) -> 0.00089283781 | J22: =IF(OR(ROW()=2,A22<>A21,B22<>B21),100000,J21-K21) -> 99622.989 | K22: =J22*I22 -> 88.947172 | L22: =IF(C22=85,J22/H22,D22*J22-(D22-E22)*K22) -> 398314.06 | M22: =SUMIFS(L:L,A:A,A22,B:B,B22,C:C,">="&C22) -> 7930339.2 | N22: =M22/J22 -> 79.603505 | P22: =IF(C22=0, 85-N22, "")
A23: 2010 | B23: Mujeres | C23: 5 | D23: 5 | E23: 2.5 | F23: 193275 | G23: 17.26 | H23: =IFERROR(G23/F23,0) -> 8.9302807e-05 | I23: =IF(C23=85,1,(D23*H23)/(1+(D23-IF(E23="",D23/2,E23))*H23)) -> 0.00044641437 | J23: =IF(OR(ROW()=2,A23<>A22,B23<>B22),100000,J22-K22) -> 99534.042 | K23: =J23*I23 -> 44.433427 | L23: =IF(C23=85,J23/H23,D23*J23-(D23-E23)*K23) -> 497559.13 | M23: =SUMIFS(L:L,A:A,A23,B:B,B23,C:C,">="&C23) -> 7532025.1 | N23: =M23/J23 -> 75.672855 | P23: =IF(C23=0, 85-N23, "")
A24: 2010 | B24: Mujeres | C24: 10 | D24: 5 | E24: 2.5 | F24: 193275 | G24: 21.1 | H24: =IFERROR(G24/F24,0) -> 0.00010917087 | I24: =IF(C24=85,1,(D24*H24)/(1+(D24-IF(E24="",D24/2,E24))*H24)) -> 0.00054570541 | J24: =IF(OR(ROW()=2,A24<>A23,B24<>B23),100000,J23-K23) -> 99489.609 | K24: =J24*I24 -> 54.292018 | L24: =IF(C24=85,J24/H24,D24*J24-(D24-E24)*K24) -> 497312.31 | M24: =SUMIFS(L:L,A:A,A24,B:B,B24,C:C,">="&C24) -> 7034466 | N24: =M24/J24 -> 70.705535 | P24: =IF(C24=0, 85-N24, "")
A25: 2010 | B25: Mujeres | C25: 15 | D25: 5 | E25: 2.5 | F25: 181196 | G25: 32.37 | H25: =IFERROR(G25/F25,0) -> 0.00017864633 | I25: =IF(C25=85,1,(D25*H25)/(1+(D25-IF(E25="",D25/2,E25))*H25)) -> 0.00089283289 | J25: =IF(OR(ROW()=2,A25<>A24,B25<>B24),100000,J24-K24) -> 99435.317 | K25: =J25*I25 -> 88.779121 | L25: =IF(C25=85,J25/H25,D25*J25-(D25-E25)*K25) -> 496954.64 | M25: =SUMIFS(L:L,A:A,A25,B:B,B25,C:C,">="&C25) -> 6537153.7 | N25: =M25/J25 -> 65.742775 | P25: =IF(C25=0, 85-N25, "")
A26: 2010 | B26: Mujeres | C26: 20 | D26: 5 | E26: 2.5 | F26: 181196 | G26: 43.17 | H26: =IFERROR(G26/F26,0) -> 0.00023825029 | I26: =IF(C26=85,1,(D26*H26)/(1+(D26-IF(E26="",D26/2,E26))*H26)) -> 0.0011905423 | J26: =IF(OR(ROW()=2,A26<>A25,B26<>B25),100000,J25-K25) -> 99346.538 | K26: =J26*I26 -> 118.27626 | L26: =IF(C26=85,J26/H26,D26*J26-(D26-E26)*K26) -> 496437 | M26: =SUMIFS(L:L,A:A,A26,B:B,B26,C:C,">="&C26) -> 6040199 | N26: =M26/J26 -> 60.799291 | P26: =IF(C26=0, 85-N26, "")
A27: 2010 | B27: Mujeres | C27: 25 | D27: 5 | E27: 2.5 | F27: 169116 | G27: 53.73 | H27: =IFERROR(G27/F27,0) -> 0.00031771092 | I27: =IF(C27=85,1,(D27*H27)/(1+(D27-IF(E27="",D27/2,E27))*H27)) -> 0.0015872939 | J27: =IF(OR(ROW()=2,A27<>A26,B27<>B26),100000,J26-K26) -> 99228.261 | K27: =J27*I27 -> 157.50441 | L27: =IF(C27=85,J27/H27,D27*J27-(D27-E27)*K27) -> 495747.55 | M27: =SUMIFS(L:L,A:A,A27,B:B,B27,C:C,">="&C27) -> 5543762 | N27: =M27/J27 -> 55.868781 | P27: =IF(C27=0, 85-N27, "")
A28: 2010 | B28: Mujeres | C28: 30 | D28: 5 | E28: 2.5 | F28: 169116 | G28: 73.9 | H28: =IFERROR(G28/F28,0) -> 0.00043697817 | I28: =IF(C28=85,1,(D28*H28)/(1+(D28-IF(E28="",D28/2,E28))*H28)) -> 0.0021825066 | J28: =IF(OR(ROW()=2,A28<>A27,B28<>B27),100000,J27-K27) -> 99070.757 | K28: =J28*I28 -> 216.22258 | L28: =IF(C28=85,J28/H28,D28*J28-(D28-E28)*K28) -> 494813.23 | M28: =SUMIFS(L:L,A:A,A28,B:B,B28,C:C,">="&C28) -> 5048014.5 | N28: =M28/J28 -> 50.953628 | P28: =IF(C28=0, 85-N28, "")
A29: 2010 | B29: Mujeres | C29: 35 | D29: 5 | E29: 2.5 | F29: 157036 | G29: 99.87 | H29: =IFERROR(G29/F29,0) -> 0.00063596882 | I29: =IF(C29=85,1,(D29*H29)/(1+(D29-IF(E29="",D29/2,E29))*H29)) -> 0.0031747964 | J29: =IF(OR(ROW()=2,A29<>A28,B29<>B28),100000,J28-K28) -> 98854.534 | K29: =J29*I29 -> 313.84302 | L29: =IF(C29=85,J29/H29,D29*J29-(D29-E29)*K29) -> 493488.06 | M29: =SUMIFS(L:L,A:A,A29,B:B,B29,C:C,">="&C29) -> 4553201.3 | N29: =M29/J29 -> 46.05961 | P29: =IF(C29=0, 85-N29, "")
A30: 2010 | B30: Mujeres | C30: 40 | D30: 5 | E30: 2.5 | F30: 144956 | G30: 144.17 | H30: =IFERROR(G30/F30,0) -> 0.00099457766 | I30: =IF(C30=85,1,(D30*H30)/(1+(D30-IF(E30="",D30/2,E30))*H30)) -> 0.0049605542 | J30: =IF(OR(ROW()=2,A30<>A29,B30<>B29),100000,J29-K29) -> 98540.691 | K30: =J30*I30 -> 488.81644 | L30: =IF(C30=85,J30/H30,D30*J30-(D30-E30)*K30) -> 491481.42 | M30: =SUMIFS(L:L,A:A,A30,B:B,B30,C:C,">="&C30) -> 4059713.2 | N30: =M30/J30 -> 41.198343 | P30: =IF(C30=0, 85-N30, "")
A31: 2010 | B31: Mujeres | C31: 45 | D31: 5 | E31: 2.5 | F31: 132877 | G31: 225.06 | H31: =IFERROR(G31/F31,0) -> 0.0016937468 | I31: =IF(C31=85,1,(D31*H31)/(1+(D31-IF(E31="",D31/2,E31))*H31)) -> 0.0084330257 | J31: =IF(OR(ROW()=2,A31<>A30,B31<>B30),100000,J30-K30) -> 98051.875 | K31: =J31*I31 -> 826.87398 | L31: =IF(C31=85,J31/H31,D31*J31-(D31-E31)*K31) -> 488192.19 | M31: =SUMIFS(L:L,A:A,A31,B:B,B31,C:C,">="&C31) -> 3568231.8 | N31: =M31/J31 -> 36.391265 | P31: =IF(C31=0, 85-N31, "")
A32: 2010 | B32: Mujeres | C32: 50 | D32: 5 | E32: 2.5 | F32: 120797 | G32: 337.91 | H32: =IFERROR(G32/F32,0) -> 0.0027973377 | I32: =IF(C32=85,1,(D32*H32)/(1+(D32-IF(E32="",D32/2,E32))*H32)) -> 0.013889554 | J32: =IF(OR(ROW()=2,A32<>A31,B32<>B31),100000,J31-K31) -> 97225.001 | K32: =J32*I32 -> 1350.4119 | L32: =IF(C32=85,J32/H32,D32*J32-(D32-E32)*K32) -> 482748.98 | M32: =SUMIFS(L:L,A:A,A32,B:B,B32,C:C,">="&C32) -> 3080039.6 | N32: =M32/J32 -> 31.679502 | P32: =IF(C32=0, 85-N32, "")
... A38: 2010 | B38: Mujeres | C38: 80 | D38: 5 | E38: 2.5 | F38: 48319 | G38: 3117.48 | H38: =IFERROR(G38/F38,0) -> 0.064518719 | I38: =IF(C38=85,1,(D38*H38)/(1+(D38-IF(E38="",D38/2,E38))*H38)) -> 0.27778738 | J38: =IF(OR(ROW()=2,A38<>A37,B38<>B37),100000,J37-K37) -> 62619.221 | K38: =J38*I38 -> 17394.829 | L38: =IF(C38=85,J38/H38,D38*J38-(D38-E38)*K38) -> 269609.03 | M38: =SUMIFS(L:L,A:A,A38,B:B,B38,C:C,">="&C38) -> 486685.58 | N38: =M38/J38 -> 7.7721437 | P38: =IF(C38=0, 85-N38, "")
A39: 2010 | B39: Mujeres | C39: 85 | D39: 999 | F39: 36239 | G39: 7549.81 | H39: =IFERROR(G39/F39,0) -> 0.20833384 | I39: =IF(C39=85,1,(D39*H39)/(1+(D39-IF(E39="",D39/2,E39))*H39)) -> 1 | J39: =IF(OR(ROW()=2,A39<>A38,B39<>B38),100000,J38-K38) -> 45224.392 | K39: =J39*I39 -> 45224.392 | L39: =IF(C39=85,J39/H39,D39*J39-(D39-E39)*K39) -> 217076.55 | M39: =SUMIFS(L:L,A:A,A39,B:B,B39,C:C,">="&C39) -> 217076.55 | N39: =M39/J39 -> 4.7999883 | P39: =IF(C39=0, 85-N39, "")
A40: 2019 | B40: Hombres | C40: 0 | D40: 1 | E40: 0.1 | F40: 43436 | G40: 258.14 | H40: =IFERROR(G40/F40,0) -> 0.0059429966 | I40: =IF(C40=85,1,(D40*H40)/(1+(D40-IF(E40="",D40/2,E40))*H40)) -> 0.0059113784 | J40: =IF(OR(ROW()=2,A40<>A39,B40<>B39),100000,J39-K39) -> 100000 | K40: =J40*I40 -> 591.13784 | L40: =IF(C40=85,J40/H40,D40*J40-(D40-E40)*K40) -> 99467.976 | M40: =SUMIFS(L:L,A:A,A40,B:B,B40,C:C,">="&C40) -> 7479999.5 | N40: =M40/J40 -> 74.799995 | P40: =IF(C40=0, 85-N40, "") -> 10.200005
A41: 2019 | B41: Hombres | C41: 1 | D41: 4 | E41: 2 | F41: 173745 | G41: 68.52 | H41: =IFERROR(G41/F41,0) -> 0.00039437106 | I41: =IF(C41=85,1,(D41*H41)/(1+(D41-IF(E41="",D41/2,E41))*H41)) -> 0.001576241 | J41: =IF(OR(ROW()=2,A41<>A40,B41<>B40),100000,J40-K40) -> 99408.862 | K41: =J41*I41 -> 156.69232 | L41: =IF(C41=85,J41/H41,D41*J41-(D41-E41)*K41) -> 397322.06 | M41: =SUMIFS(L:L,A:A,A41,B:B,B41,C:C,">="&C41) -> 7380531.5 | N41: =M41/J41 -> 74.244201 | P41: =IF(C41=0, 85-N41, "")
A42: 2019 | B42: Hombres | C42: 5 | D42: 5 | E42: 2.5 | F42: 231660 | G42: 36.53 | H42: =IFERROR(G42/F42,0) -> 0.00015768799 | I42: =IF(C42=85,1,(D42*H42)/(1+(D42-IF(E42="",D42/2,E42))*H42)) -> 0.00078812926 | J42: =IF(OR(ROW()=2,A42<>A41,B42<>B41),100000,J41-K41) -> 99252.17 | K42: =J42*I42 -> 78.223539 | L42: =IF(C42=85,J42/H42,D42*J42-(D42-E42)*K42) -> 496065.29 | M42: =SUMIFS(L:L,A:A,A42,B:B,B42,C:C,">="&C42) -> 6983209.5 | N42: =M42/J42 -> 70.358255 | P42: =IF(C42=0, 85-N42, "")
A43: 2019 | B43: Hombres | C43: 10 | D43: 5 | E43: 2.5 | F43: 231660 | G43: 48.72 | H43: =IFERROR(G43/F43,0) -> 0.00021030821 | I43: =IF(C43=85,1,(D43*H43)/(1+(D43-IF(E43="",D43/2,E43))*H43)) -> 0.0010509885 | J43: =IF(OR(ROW()=2,A43<>A42,B43<>B42),100000,J42-K42) -> 99173.946 | K43: =J43*I43 -> 104.23067 | L43: =IF(C43=85,J43/H43,D43*J43-(D43-E43)*K43) -> 495609.15 | M43: =SUMIFS(L:L,A:A,A43,B:B,B43,C:C,">="&C43) -> 6487144.2 | N43: =M43/J43 -> 65.411778 | P43: =IF(C43=0, 85-N43, "")
A44: 2019 | B44: Hombres | C44: 15 | D44: 5 | E44: 2.5 | F44: 217181 | G44: 102.83 | H44: =IFERROR(G44/F44,0) -> 0.00047347604 | I44: =IF(C44=85,1,(D44*H44)/(1+(D44-IF(E44="",D44/2,E44))*H44)) -> 0.0023645813 | J44: =IF(OR(ROW()=2,A44<>A43,B44<>B43),100000,J43-K43) -> 99069.716 | K44: =J44*I44 -> 234.25839 | L44: =IF(C44=85,J44/H44,D44*J44-(D44-E44)*K44) -> 494762.93 | M44: =SUMIFS(L:L,A:A,A44,B:B,B44,C:C,">="&C44) -> 5991535 | N44: =M44/J44 -> 60.477967 | P44: =IF(C44=0, 85-N44, "")
A45: 2019 | B45: Hombres | C45: 20 | D45: 5 | E45: 2.5 | F45: 217181 | G45: 171.51 | H45: =IFERROR(G45/F45,0) -> 0.00078970997 | I45: =IF(C45=85,1,(D45*H45)/(1+(D45-IF(E45="",D45/2,E45))*H45)) -> 0.0039407697 | J45: =IF(OR(ROW()=2,A45<>A44,B45<>B44),100000,J44-K44) -> 98835.457 | K45: =J45*I45 -> 389.48777 | L45: =IF(C45=85,J45/H45,D45*J45-(D45-E45)*K45) -> 493203.57 | M45: =SUMIFS(L:L,A:A,A45,B:B,B45,C:C,">="&C45) -> 5496772.1 | N45: =M45/J45 -> 55.615386 | P45: =IF(C45=0, 85-N45, "")
A46: 2019 | B46: Hombres | C46: 25 | D46: 5 | E46: 2.5 | F46: 202703 | G46: 213.58 | H46: =IFERROR(G46/F46,0) -> 0.0010536598 | I46: =IF(C46=85,1,(D46*H46)/(1+(D46-IF(E46="",D46/2,E46))*H46)) -> 0.0052544579 | J46: =IF(OR(ROW()=2,A46<>A45,B46<>B45),100000,J45-K45) -> 98445.969 | K46: =J46*I46 -> 517.2802 | L46: =IF(C46=85,J46/H46,D46*J46-(D46-E46)*K46) -> 490936.65 | M46: =SUMIFS(L:L,A:A,A46,B:B,B46,C:C,">="&C46) -> 5003568.5 | N46: =M46/J46 -> 50.825529 | P46: =IF(C46=0, 85-N46, "")
A47: 2019 | B47: Hombres | C47: 30 | D47: 5 | E47: 2.5 | F47: 202703 | G47: 267.15 | H47: =IFERROR(G47/F47,0) -> 0.0013179381 | I47: =IF(C47=85,1,(D47*H47)/(1+(D47-IF(E47="",D47/2,E47))*H47)) -> 0.0065680496 | J47: =IF(OR(ROW()=2,A47<>A46,B47<>B46),100000,J46-K46) -> 97928.689 | K47: =J47*I47 -> 643.20049 | L47: =IF(C47=85,J47/H47,D47*J47-(D47-E47)*K47) -> 488035.45 | M47: =SUMIFS(L:L,A:A,A47,B:B,B47,C:C,">="&C47) -> 4512631.9 | N47: =M47/J47 -> 46.080795 | P47: =IF(C47=0, 85-N47, "")
A48: 2019 | B48: Hombres | C48: 35 | D48: 5 | E48: 2.5 | F48: 188224 | G48: 322.81 | H48: =IFERROR(G48/F48,0) -> 0.001715031 | I48: =IF(C48=85,1,(D48*H48)/(1+(D48-IF(E48="",D48/2,E48))*H48)) -> 0.0085385455 | J48: =IF(OR(ROW()=2,A48<>A47,B48<>B47),100000,J47-K47) -> 97285.489 | K48: =J48*I48 -> 830.67657 | L48: =IF(C48=85,J48/H48,D48*J48-(D48-E48)*K48) -> 484350.75 | M48: =SUMIFS(L:L,A:A,A48,B:B,B48,C:C,">="&C48) -> 4024596.4 | N48: =M48/J48 -> 41.368928 | P48: =IF(C48=0, 85-N48, "")
A49: 2019 | B49: Hombres | C49: 40 | D49: 5 | E49: 2.5 | F49: 173745 | G49: 413.27 | H49: =IFERROR(G49/F49,0) -> 0.0023786008 | I49: =IF(C49=85,1,(D49*H49)/(1+(D49-IF(E49="",D49/2,E49))*H49)) -> 0.0118227 | J49: =IF(OR(ROW()=2,A49<>A48,B49<>B48),100000,J48-K48) -> 96454.812 | K49: =J49*I49 -> 1140.3563 | L49: =IF(C49=85,J49/H49,D49*J49-(D49-E49)*K49) -> 479423.17 | M49: =SUMIFS(L:L,A:A,A49,B:B,B49,C:C,">="&C49) -> 3540245.7 | N49: =M49/J49 -> 36.703671 | P49: =IF(C49=0, 85-N49, "")
A50: 2019 | B50: Hombres | C50: 45 | D50: 5 | E50: 2.5 | F50: 159266 | G50: 591.24 | H50: =IFERROR(G50/F50,0) -> 0.0037122801 | I50: =IF(C50=85,1,(D50*H50)/(1+(D50-IF(E50="",D50/2,E50))*H50)) -> 0.018390722 | J50: =IF(OR(ROW()=2,A50<>A49,B50<>B49),100000,J49-K49) -> 95314.456 | K50: =J50*I50 -> 1752.9016 | L50: =IF(C50=85,J50/H50,D50*J50-(D50-E50)*K50) -> 472190.03 | M50: =SUMIFS(L:L,A:A,A50,B:B,B50,C:C,">="&C50) -> 3060822.5 | N50: =M50/J50 -> 32.112889 | P50: =IF(C50=0, 85-N50, "")
...

Sheet Resumen_EV
A1: anio | B1: sexo | C1: e0_calculada | D1: e0_referencia | E1: diferencia | F1: comentario | H1: Año | I1: Hombres | J1: Mujeres
A2: 2010 | B2: Hombres | C2: =SUMIFS(base_nuevo_leon!N:N, base_nuevo_leon!A:A,A2,base_nuevo_leon!B:B,B2,base_nuevo_leon!C:C,0) -> 74.599951 | D2: 74.6 | E2: =C2-D2 -> -4.9335575e-05 | F2: Referencia pre-pandemia | H2: 2010 | I2: 74.6 | J2: 80.3
A3: 2010 | B3: Mujeres | C3: =SUMIFS(base_nuevo_leon!N:N, base_nuevo_leon!A:A,A3,base_nuevo_leon!B:B,B3,base_nuevo_leon!C:C,0) -> 80.299999 | D3: 80.3 | E3: =C3-D3 -> -1.2342976e-06 | F3: Referencia pre-pandemia | H3: 2019 | I3: 74.8 | J3: 80.5
A4: 2019 | B4: Hombres | C4: =SUMIFS(base_nuevo_leon!N:N, base_nuevo_leon!A:A,A4,base_nuevo_leon!B:B,B4,base_nuevo_leon!C:C,0) -> 74.799995 | D4: 74.8 | E4: =C4-D4 -> -5.0262118e-06 | F4: Referencia pre-pandemia | H4: 2021 | I4: 67.1 | J4: 75.6
A5: 2019 | B5: Mujeres | C5: =SUMIFS(base_nuevo_leon!N:N, base_nuevo_leon!A:A,A5,base_nuevo_leon!B:B,B5,base_nuevo_leon!C:C,0) -> 80.499949 | D5: 80.5 | E5: =C5-D5 -> -5.1178023e-05 | F5: Referencia pre-pandemia
A6: 2021 | B6: Hombres | C6: =SUMIFS(base_nuevo_leon!N:N, base_nuevo_leon!A:A,A6,base_nuevo_leon!B:B,B6,base_nuevo_leon!C:C,0) -> 67.099996 | D6: 67.1 | E6: =C6-D6 -> -3.512476e-06 | F6: Disminución en 2021 por efecto COVID
A7: 2021 | B7: Mujeres | C7: =SUMIFS(base_nuevo_leon!N:N, base_nuevo_leon!A:A,A7,base_nuevo_leon!B:B,B7,base_nuevo_leon!C:C,0) -> 75.599986 | D7: 75.6 | E7: =C7-D7 -> -1.4367127e-05 | F7: Disminución en 2021 por efecto COVID
